INFO:apscheduler.scheduler:Scheduler started
INFO:telegram.ext.updater:Received signal 2 (SIGINT), stopping...
INFO:apscheduler.scheduler:Scheduler has been shut down
WARNING:telegram.ext.updater:Exiting immediately!
INFO:apscheduler.scheduler:Scheduler started
ERROR:telegram.ext.dispatcher:No error handlers are registered, logging exception.
Traceback (most recent call last):
  File "C:\Python39\lib\site-packages\telegram\ext\dispatcher.py", line 442, in process_update
    handler.handle_update(update, self, check, context)
  File "C:\Python39\lib\site-packages\telegram\ext\handler.py", line 160, in handle_update
    return self.callback(update, context)
  File "C:\LearnPython\lesson1\bot\learn_python_alex_bot.py", line 8, in greet_user
    print(1/0)
ZeroDivisionError: division by zero
INFO:telegram.ext.updater:Received signal 2 (SIGINT), stopping...
INFO:apscheduler.scheduler:Scheduler has been shut down
WARNING:telegram.ext.updater:Exiting immediately!
INFO:root:Бот стартовал
INFO:apscheduler.scheduler:Scheduler started
INFO:telegram.ext.updater:Received signal 2 (SIGINT), stopping...
INFO:apscheduler.scheduler:Scheduler has been shut down
WARNING:telegram.ext.updater:Exiting immediately!
21-Feb-21 22:47:53 - Бот стартовал
21-Feb-21 22:47:53 - Scheduler started
21-Feb-21 22:48:12 - Received signal 2 (SIGINT), stopping...
21-Feb-21 22:48:12 - Scheduler has been shut down
21-Feb-21 22:57:24 - Бот стартовал
21-Feb-21 22:57:24 - Scheduler started
21-Feb-21 22:57:50 - No error handlers are registered, logging exception.
Traceback (most recent call last):
  File "C:\Python39\lib\site-packages\telegram\ext\dispatcher.py", line 442, in process_update
    handler.handle_update(update, self, check, context)
  File "C:\Python39\lib\site-packages\telegram\ext\handler.py", line 160, in handle_update
    return self.callback(update, context)
  File "C:\LearnPython\lesson1\bot\learn_python_alex_bot.py", line 15, in talk_to_me
    update.message.reply.text(text)
AttributeError: 'Message' object has no attribute 'reply'
21-Feb-21 23:01:15 - Received signal 2 (SIGINT), stopping...
21-Feb-21 23:01:15 - Scheduler has been shut down
21-Feb-21 23:01:21 - Exiting immediately!
21-Feb-21 23:01:24 - Бот стартовал
21-Feb-21 23:01:24 - Scheduler started
21-Feb-21 23:06:38 - Received signal 2 (SIGINT), stopping...
21-Feb-21 23:06:38 - Scheduler has been shut down
21-Feb-21 23:06:38 - Exiting immediately!
21-Feb-21 23:06:41 - Бот стартовал
21-Feb-21 23:06:41 - Scheduler started
21-Feb-21 23:09:24 - Received signal 2 (SIGINT), stopping...
21-Feb-21 23:09:24 - Scheduler has been shut down
21-Feb-21 23:09:24 - Exiting immediately!
21-Feb-21 23:09:26 - Бот стартовал
21-Feb-21 23:09:26 - Scheduler started
21-Feb-21 23:13:29 - Received signal 2 (SIGINT), stopping...
21-Feb-21 23:13:29 - Scheduler has been shut down
21-Feb-21 23:13:29 - Exiting immediately!
21-Feb-21 23:20:41 - Бот стартовал
21-Feb-21 23:20:41 - Scheduler started
21-Feb-21 23:21:10 - Received signal 2 (SIGINT), stopping...
21-Feb-21 23:21:10 - Scheduler has been shut down
21-Feb-21 23:22:24 - Бот стартовал
21-Feb-21 23:22:24 - Scheduler started
21-Feb-21 23:22:51 - Received signal 2 (SIGINT), stopping...
21-Feb-21 23:22:51 - Scheduler has been shut down
21-Feb-21 23:24:36 - Бот стартовал
21-Feb-21 23:24:36 - Scheduler started
21-Feb-21 23:43:35 - Received signal 2 (SIGINT), stopping...
21-Feb-21 23:43:35 - Scheduler has been shut down
21-Feb-21 23:43:42 - Exiting immediately!
21-Feb-21 23:43:45 - Бот стартовал
21-Feb-21 23:43:45 - Scheduler started
21-Feb-21 23:46:04 - Received signal 2 (SIGINT), stopping...
21-Feb-21 23:46:04 - Scheduler has been shut down
21-Feb-21 23:46:04 - Exiting immediately!
21-Feb-21 23:46:07 - Бот стартовал
21-Feb-21 23:46:07 - Scheduler started
21-Feb-21 23:47:36 - Received signal 2 (SIGINT), stopping...
21-Feb-21 23:47:36 - Scheduler has been shut down
21-Feb-21 23:47:37 - Exiting immediately!
21-Feb-21 23:47:40 - Бот стартовал
21-Feb-21 23:47:40 - Scheduler started
21-Feb-21 23:48:22 - Received signal 2 (SIGINT), stopping...
21-Feb-21 23:48:22 - Scheduler has been shut down
21-Feb-21 23:48:22 - Exiting immediately!
21-Feb-21 23:48:24 - Бот стартовал
21-Feb-21 23:48:24 - Scheduler started
21-Feb-21 23:50:29 - Received signal 2 (SIGINT), stopping...
21-Feb-21 23:50:29 - Scheduler has been shut down
21-Feb-21 23:50:29 - Exiting immediately!
21-Feb-21 23:50:39 - Бот стартовал
21-Feb-21 23:50:39 - Scheduler started
21-Feb-21 23:51:30 - No error handlers are registered, logging exception.
Traceback (most recent call last):
  File "C:\Python39\lib\site-packages\telegram\ext\dispatcher.py", line 442, in process_update
    handler.handle_update(update, self, check, context)
  File "C:\Python39\lib\site-packages\telegram\ext\handler.py", line 160, in handle_update
    return self.callback(update, context)
  File "C:\LearnPython\lesson1\bot\learn_python_alex_bot1.py", line 15, in planet_request
    planet = ephem.user_planet()
AttributeError: module 'ephem' has no attribute 'user_planet'
21-Feb-21 23:55:06 - Received signal 2 (SIGINT), stopping...
21-Feb-21 23:55:06 - Scheduler has been shut down
21-Feb-21 23:55:06 - Exiting immediately!
21-Feb-21 23:55:08 - Бот стартовал
21-Feb-21 23:55:08 - Scheduler started
21-Feb-21 23:55:12 - No error handlers are registered, logging exception.
Traceback (most recent call last):
  File "C:\Python39\lib\site-packages\telegram\ext\dispatcher.py", line 442, in process_update
    handler.handle_update(update, self, check, context)
  File "C:\Python39\lib\site-packages\telegram\ext\handler.py", line 160, in handle_update
    return self.callback(update, context)
  File "C:\LearnPython\lesson1\bot\learn_python_alex_bot1.py", line 17, in planet_request
    planet = ephem.user_planet()
AttributeError: module 'ephem' has no attribute 'user_planet'
21-Feb-21 23:55:13 - No error handlers are registered, logging exception.
Traceback (most recent call last):
  File "C:\Python39\lib\site-packages\telegram\ext\dispatcher.py", line 442, in process_update
    handler.handle_update(update, self, check, context)
  File "C:\Python39\lib\site-packages\telegram\ext\handler.py", line 160, in handle_update
    return self.callback(update, context)
  File "C:\LearnPython\lesson1\bot\learn_python_alex_bot1.py", line 17, in planet_request
    planet = ephem.user_planet()
AttributeError: module 'ephem' has no attribute 'user_planet'
21-Feb-21 23:55:20 - No error handlers are registered, logging exception.
Traceback (most recent call last):
  File "C:\Python39\lib\site-packages\telegram\ext\dispatcher.py", line 442, in process_update
    handler.handle_update(update, self, check, context)
  File "C:\Python39\lib\site-packages\telegram\ext\handler.py", line 160, in handle_update
    return self.callback(update, context)
  File "C:\LearnPython\lesson1\bot\learn_python_alex_bot1.py", line 17, in planet_request
    planet = ephem.user_planet()
AttributeError: module 'ephem' has no attribute 'user_planet'
21-Feb-21 23:56:24 - Received signal 2 (SIGINT), stopping...
21-Feb-21 23:56:24 - Scheduler has been shut down
21-Feb-21 23:56:24 - Exiting immediately!
21-Feb-21 23:56:26 - Бот стартовал
21-Feb-21 23:56:26 - Scheduler started
21-Feb-21 23:56:31 - No error handlers are registered, logging exception.
Traceback (most recent call last):
  File "C:\Python39\lib\site-packages\telegram\ext\dispatcher.py", line 442, in process_update
    handler.handle_update(update, self, check, context)
  File "C:\Python39\lib\site-packages\telegram\ext\handler.py", line 160, in handle_update
    return self.callback(update, context)
  File "C:\LearnPython\lesson1\bot\learn_python_alex_bot1.py", line 17, in planet_request
    planet = ephem.user_planet(now.strftime("%d/%m/%Y"))
AttributeError: module 'ephem' has no attribute 'user_planet'
21-Feb-21 23:57:22 - No error handlers are registered, logging exception.
Traceback (most recent call last):
  File "C:\Python39\lib\site-packages\telegram\ext\dispatcher.py", line 442, in process_update
    handler.handle_update(update, self, check, context)
  File "C:\Python39\lib\site-packages\telegram\ext\handler.py", line 160, in handle_update
    return self.callback(update, context)
  File "C:\LearnPython\lesson1\bot\learn_python_alex_bot1.py", line 17, in planet_request
    planet = ephem.user_planet(now.strftime("%d/%m/%Y"))
AttributeError: module 'ephem' has no attribute 'user_planet'
22-Feb-21 08:29:55 - Error while getting Updates: urllib3 HTTPError ('Connection aborted.', ConnectionResetError(10054, 'Удаленный хост принудительно разорвал существующее подключение', None, 10054, None))
22-Feb-21 08:29:55 - No error handlers are registered, logging exception.
Traceback (most recent call last):
  File "C:\Python39\lib\site-packages\telegram\vendor\ptb_urllib3\urllib3\connectionpool.py", line 614, in urlopen
    httplib_response = self._make_request(conn, method, url,
  File "C:\Python39\lib\site-packages\telegram\vendor\ptb_urllib3\urllib3\connectionpool.py", line 402, in _make_request
    six.raise_from(e, None)
  File "<string>", line 2, in raise_from
  File "C:\Python39\lib\site-packages\telegram\vendor\ptb_urllib3\urllib3\connectionpool.py", line 398, in _make_request
    httplib_response = conn.getresponse()
  File "C:\Python39\lib\http\client.py", line 1347, in getresponse
    response.begin()
  File "C:\Python39\lib\http\client.py", line 307, in begin
    version, status, reason = self._read_status()
  File "C:\Python39\lib\http\client.py", line 268, in _read_status
    line = str(self.fp.readline(_MAXLINE + 1), "iso-8859-1")
  File "C:\Python39\lib\socket.py", line 704, in readinto
    return self._sock.recv_into(b)
  File "C:\Python39\lib\ssl.py", line 1241, in recv_into
    return self.read(nbytes, buffer)
  File "C:\Python39\lib\ssl.py", line 1099, in read
    return self._sslobj.read(len, buffer)
ConnectionResetError: [WinError 10054] Удаленный хост принудительно разорвал существующее подключение

During handling of the above exception, another exception occurred:

Traceback (most recent call last):
  File "C:\Python39\lib\site-packages\telegram\utils\request.py", line 252, in _request_wrapper
    resp = self._con_pool.request(*args, **kwargs)
  File "C:\Python39\lib\site-packages\telegram\vendor\ptb_urllib3\urllib3\request.py", line 68, in request
    return self.request_encode_body(method, url, fields=fields,
  File "C:\Python39\lib\site-packages\telegram\vendor\ptb_urllib3\urllib3\request.py", line 148, in request_encode_body
    return self.urlopen(method, url, **extra_kw)
  File "C:\Python39\lib\site-packages\telegram\vendor\ptb_urllib3\urllib3\poolmanager.py", line 244, in urlopen
    response = conn.urlopen(method, u.request_uri, **kw)
  File "C:\Python39\lib\site-packages\telegram\vendor\ptb_urllib3\urllib3\connectionpool.py", line 665, in urlopen
    retries = retries.increment(method, url, error=e, _pool=self,
  File "C:\Python39\lib\site-packages\telegram\vendor\ptb_urllib3\urllib3\util\retry.py", line 347, in increment
    raise six.reraise(type(error), error, _stacktrace)
  File "C:\Python39\lib\site-packages\telegram\vendor\ptb_urllib3\urllib3\packages\six.py", line 685, in reraise
    raise value.with_traceback(tb)
  File "C:\Python39\lib\site-packages\telegram\vendor\ptb_urllib3\urllib3\connectionpool.py", line 614, in urlopen
    httplib_response = self._make_request(conn, method, url,
  File "C:\Python39\lib\site-packages\telegram\vendor\ptb_urllib3\urllib3\connectionpool.py", line 402, in _make_request
    six.raise_from(e, None)
  File "<string>", line 2, in raise_from
  File "C:\Python39\lib\site-packages\telegram\vendor\ptb_urllib3\urllib3\connectionpool.py", line 398, in _make_request
    httplib_response = conn.getresponse()
  File "C:\Python39\lib\http\client.py", line 1347, in getresponse
    response.begin()
  File "C:\Python39\lib\http\client.py", line 307, in begin
    version, status, reason = self._read_status()
  File "C:\Python39\lib\http\client.py", line 268, in _read_status
    line = str(self.fp.readline(_MAXLINE + 1), "iso-8859-1")
  File "C:\Python39\lib\socket.py", line 704, in readinto
    return self._sock.recv_into(b)
  File "C:\Python39\lib\ssl.py", line 1241, in recv_into
    return self.read(nbytes, buffer)
  File "C:\Python39\lib\ssl.py", line 1099, in read
    return self._sslobj.read(len, buffer)
telegram.vendor.ptb_urllib3.urllib3.exceptions.ProtocolError: ('Connection aborted.', ConnectionResetError(10054, 'Удаленный хост принудительно разорвал существующее подключение', None, 10054, None))

The above exception was the direct cause of the following exception:

Traceback (most recent call last):
  File "C:\Python39\lib\site-packages\telegram\ext\updater.py", line 465, in _network_loop_retry
    if not action_cb():
  File "C:\Python39\lib\site-packages\telegram\ext\updater.py", line 416, in polling_action_cb
    updates = self.bot.get_updates(
  File "C:\Python39\lib\site-packages\telegram\bot.py", line 117, in decorator
    result = func(*args, **kwargs)
  File "C:\Python39\lib\site-packages\telegram\bot.py", line 2725, in get_updates
    result = self._post(
  File "C:\Python39\lib\site-packages\telegram\bot.py", line 235, in _post
    return self.request.post(f'{self.base_url}/{endpoint}', data=data, timeout=timeout)
  File "C:\Python39\lib\site-packages\telegram\utils\request.py", line 349, in post
    result = self._request_wrapper(
  File "C:\Python39\lib\site-packages\telegram\utils\request.py", line 258, in _request_wrapper
    raise NetworkError(f'urllib3 HTTPError {error}') from error
telegram.error.NetworkError: urllib3 HTTPError ('Connection aborted.', ConnectionResetError(10054, 'Удаленный хост принудительно разорвал существующее подключение', None, 10054, None))
22-Feb-21 10:27:35 - Received signal 2 (SIGINT), stopping...
22-Feb-21 10:27:35 - Scheduler has been shut down
22-Feb-21 10:27:35 - Exiting immediately!
22-Feb-21 10:27:38 - Бот стартовал
22-Feb-21 10:27:38 - Scheduler started
22-Feb-21 10:28:23 - Error while getting Updates: Conflict: terminated by other getUpdates request; make sure that only one bot instance is running
22-Feb-21 10:28:23 - No error handlers are registered, logging exception.
Traceback (most recent call last):
  File "C:\Python39\lib\site-packages\telegram\ext\updater.py", line 465, in _network_loop_retry
    if not action_cb():
  File "C:\Python39\lib\site-packages\telegram\ext\updater.py", line 416, in polling_action_cb
    updates = self.bot.get_updates(
  File "C:\Python39\lib\site-packages\telegram\bot.py", line 117, in decorator
    result = func(*args, **kwargs)
  File "C:\Python39\lib\site-packages\telegram\bot.py", line 2725, in get_updates
    result = self._post(
  File "C:\Python39\lib\site-packages\telegram\bot.py", line 235, in _post
    return self.request.post(f'{self.base_url}/{endpoint}', data=data, timeout=timeout)
  File "C:\Python39\lib\site-packages\telegram\utils\request.py", line 349, in post
    result = self._request_wrapper(
  File "C:\Python39\lib\site-packages\telegram\utils\request.py", line 276, in _request_wrapper
    raise Conflict(message)
telegram.error.Conflict: Conflict: terminated by other getUpdates request; make sure that only one bot instance is running
22-Feb-21 10:28:27 - Error while getting Updates: Conflict: terminated by other getUpdates request; make sure that only one bot instance is running
22-Feb-21 10:28:27 - No error handlers are registered, logging exception.
Traceback (most recent call last):
  File "C:\Python39\lib\site-packages\telegram\ext\updater.py", line 465, in _network_loop_retry
    if not action_cb():
  File "C:\Python39\lib\site-packages\telegram\ext\updater.py", line 416, in polling_action_cb
    updates = self.bot.get_updates(
  File "C:\Python39\lib\site-packages\telegram\bot.py", line 117, in decorator
    result = func(*args, **kwargs)
  File "C:\Python39\lib\site-packages\telegram\bot.py", line 2725, in get_updates
    result = self._post(
  File "C:\Python39\lib\site-packages\telegram\bot.py", line 235, in _post
    return self.request.post(f'{self.base_url}/{endpoint}', data=data, timeout=timeout)
  File "C:\Python39\lib\site-packages\telegram\utils\request.py", line 349, in post
    result = self._request_wrapper(
  File "C:\Python39\lib\site-packages\telegram\utils\request.py", line 276, in _request_wrapper
    raise Conflict(message)
telegram.error.Conflict: Conflict: terminated by other getUpdates request; make sure that only one bot instance is running
22-Feb-21 10:28:32 - Error while getting Updates: Conflict: terminated by other getUpdates request; make sure that only one bot instance is running
22-Feb-21 10:28:32 - No error handlers are registered, logging exception.
Traceback (most recent call last):
  File "C:\Python39\lib\site-packages\telegram\ext\updater.py", line 465, in _network_loop_retry
    if not action_cb():
  File "C:\Python39\lib\site-packages\telegram\ext\updater.py", line 416, in polling_action_cb
    updates = self.bot.get_updates(
  File "C:\Python39\lib\site-packages\telegram\bot.py", line 117, in decorator
    result = func(*args, **kwargs)
  File "C:\Python39\lib\site-packages\telegram\bot.py", line 2725, in get_updates
    result = self._post(
  File "C:\Python39\lib\site-packages\telegram\bot.py", line 235, in _post
    return self.request.post(f'{self.base_url}/{endpoint}', data=data, timeout=timeout)
  File "C:\Python39\lib\site-packages\telegram\utils\request.py", line 349, in post
    result = self._request_wrapper(
  File "C:\Python39\lib\site-packages\telegram\utils\request.py", line 276, in _request_wrapper
    raise Conflict(message)
telegram.error.Conflict: Conflict: terminated by other getUpdates request; make sure that only one bot instance is running
22-Feb-21 10:28:37 - Error while getting Updates: Conflict: terminated by other getUpdates request; make sure that only one bot instance is running
22-Feb-21 10:28:37 - No error handlers are registered, logging exception.
Traceback (most recent call last):
  File "C:\Python39\lib\site-packages\telegram\ext\updater.py", line 465, in _network_loop_retry
    if not action_cb():
  File "C:\Python39\lib\site-packages\telegram\ext\updater.py", line 416, in polling_action_cb
    updates = self.bot.get_updates(
  File "C:\Python39\lib\site-packages\telegram\bot.py", line 117, in decorator
    result = func(*args, **kwargs)
  File "C:\Python39\lib\site-packages\telegram\bot.py", line 2725, in get_updates
    result = self._post(
  File "C:\Python39\lib\site-packages\telegram\bot.py", line 235, in _post
    return self.request.post(f'{self.base_url}/{endpoint}', data=data, timeout=timeout)
  File "C:\Python39\lib\site-packages\telegram\utils\request.py", line 349, in post
    result = self._request_wrapper(
  File "C:\Python39\lib\site-packages\telegram\utils\request.py", line 276, in _request_wrapper
    raise Conflict(message)
telegram.error.Conflict: Conflict: terminated by other getUpdates request; make sure that only one bot instance is running
22-Feb-21 10:28:44 - Error while getting Updates: Conflict: terminated by other getUpdates request; make sure that only one bot instance is running
22-Feb-21 10:28:44 - No error handlers are registered, logging exception.
Traceback (most recent call last):
  File "C:\Python39\lib\site-packages\telegram\ext\updater.py", line 465, in _network_loop_retry
    if not action_cb():
  File "C:\Python39\lib\site-packages\telegram\ext\updater.py", line 416, in polling_action_cb
    updates = self.bot.get_updates(
  File "C:\Python39\lib\site-packages\telegram\bot.py", line 117, in decorator
    result = func(*args, **kwargs)
  File "C:\Python39\lib\site-packages\telegram\bot.py", line 2725, in get_updates
    result = self._post(
  File "C:\Python39\lib\site-packages\telegram\bot.py", line 235, in _post
    return self.request.post(f'{self.base_url}/{endpoint}', data=data, timeout=timeout)
  File "C:\Python39\lib\site-packages\telegram\utils\request.py", line 349, in post
    result = self._request_wrapper(
  File "C:\Python39\lib\site-packages\telegram\utils\request.py", line 276, in _request_wrapper
    raise Conflict(message)
telegram.error.Conflict: Conflict: terminated by other getUpdates request; make sure that only one bot instance is running
22-Feb-21 10:28:53 - Error while getting Updates: Conflict: terminated by other getUpdates request; make sure that only one bot instance is running
22-Feb-21 10:28:53 - No error handlers are registered, logging exception.
Traceback (most recent call last):
  File "C:\Python39\lib\site-packages\telegram\ext\updater.py", line 465, in _network_loop_retry
    if not action_cb():
  File "C:\Python39\lib\site-packages\telegram\ext\updater.py", line 416, in polling_action_cb
    updates = self.bot.get_updates(
  File "C:\Python39\lib\site-packages\telegram\bot.py", line 117, in decorator
    result = func(*args, **kwargs)
  File "C:\Python39\lib\site-packages\telegram\bot.py", line 2725, in get_updates
    result = self._post(
  File "C:\Python39\lib\site-packages\telegram\bot.py", line 235, in _post
    return self.request.post(f'{self.base_url}/{endpoint}', data=data, timeout=timeout)
  File "C:\Python39\lib\site-packages\telegram\utils\request.py", line 349, in post
    result = self._request_wrapper(
  File "C:\Python39\lib\site-packages\telegram\utils\request.py", line 276, in _request_wrapper
    raise Conflict(message)
telegram.error.Conflict: Conflict: terminated by other getUpdates request; make sure that only one bot instance is running
22-Feb-21 10:29:04 - Error while getting Updates: Conflict: terminated by other getUpdates request; make sure that only one bot instance is running
22-Feb-21 10:29:04 - No error handlers are registered, logging exception.
Traceback (most recent call last):
  File "C:\Python39\lib\site-packages\telegram\ext\updater.py", line 465, in _network_loop_retry
    if not action_cb():
  File "C:\Python39\lib\site-packages\telegram\ext\updater.py", line 416, in polling_action_cb
    updates = self.bot.get_updates(
  File "C:\Python39\lib\site-packages\telegram\bot.py", line 117, in decorator
    result = func(*args, **kwargs)
  File "C:\Python39\lib\site-packages\telegram\bot.py", line 2725, in get_updates
    result = self._post(
  File "C:\Python39\lib\site-packages\telegram\bot.py", line 235, in _post
    return self.request.post(f'{self.base_url}/{endpoint}', data=data, timeout=timeout)
  File "C:\Python39\lib\site-packages\telegram\utils\request.py", line 349, in post
    result = self._request_wrapper(
  File "C:\Python39\lib\site-packages\telegram\utils\request.py", line 276, in _request_wrapper
    raise Conflict(message)
telegram.error.Conflict: Conflict: terminated by other getUpdates request; make sure that only one bot instance is running
22-Feb-21 10:29:19 - Error while getting Updates: Conflict: terminated by other getUpdates request; make sure that only one bot instance is running
22-Feb-21 10:29:19 - No error handlers are registered, logging exception.
Traceback (most recent call last):
  File "C:\Python39\lib\site-packages\telegram\ext\updater.py", line 465, in _network_loop_retry
    if not action_cb():
  File "C:\Python39\lib\site-packages\telegram\ext\updater.py", line 416, in polling_action_cb
    updates = self.bot.get_updates(
  File "C:\Python39\lib\site-packages\telegram\bot.py", line 117, in decorator
    result = func(*args, **kwargs)
  File "C:\Python39\lib\site-packages\telegram\bot.py", line 2725, in get_updates
    result = self._post(
  File "C:\Python39\lib\site-packages\telegram\bot.py", line 235, in _post
    return self.request.post(f'{self.base_url}/{endpoint}', data=data, timeout=timeout)
  File "C:\Python39\lib\site-packages\telegram\utils\request.py", line 349, in post
    result = self._request_wrapper(
  File "C:\Python39\lib\site-packages\telegram\utils\request.py", line 276, in _request_wrapper
    raise Conflict(message)
telegram.error.Conflict: Conflict: terminated by other getUpdates request; make sure that only one bot instance is running
22-Feb-21 10:29:40 - Error while getting Updates: Conflict: terminated by other getUpdates request; make sure that only one bot instance is running
22-Feb-21 10:29:40 - No error handlers are registered, logging exception.
Traceback (most recent call last):
  File "C:\Python39\lib\site-packages\telegram\ext\updater.py", line 465, in _network_loop_retry
    if not action_cb():
  File "C:\Python39\lib\site-packages\telegram\ext\updater.py", line 416, in polling_action_cb
    updates = self.bot.get_updates(
  File "C:\Python39\lib\site-packages\telegram\bot.py", line 117, in decorator
    result = func(*args, **kwargs)
  File "C:\Python39\lib\site-packages\telegram\bot.py", line 2725, in get_updates
    result = self._post(
  File "C:\Python39\lib\site-packages\telegram\bot.py", line 235, in _post
    return self.request.post(f'{self.base_url}/{endpoint}', data=data, timeout=timeout)
  File "C:\Python39\lib\site-packages\telegram\utils\request.py", line 349, in post
    result = self._request_wrapper(
  File "C:\Python39\lib\site-packages\telegram\utils\request.py", line 276, in _request_wrapper
    raise Conflict(message)
telegram.error.Conflict: Conflict: terminated by other getUpdates request; make sure that only one bot instance is running
22-Feb-21 10:30:15 - Received signal 2 (SIGINT), stopping...
22-Feb-21 10:30:15 - Scheduler has been shut down
22-Feb-21 10:30:15 - Exiting immediately!
22-Feb-21 10:30:17 - Бот стартовал
22-Feb-21 10:30:17 - Scheduler started
22-Feb-21 10:30:18 - Error while getting Updates: Conflict: terminated by other getUpdates request; make sure that only one bot instance is running
22-Feb-21 10:30:18 - No error handlers are registered, logging exception.
Traceback (most recent call last):
  File "C:\Python39\lib\site-packages\telegram\ext\updater.py", line 465, in _network_loop_retry
    if not action_cb():
  File "C:\Python39\lib\site-packages\telegram\ext\updater.py", line 416, in polling_action_cb
    updates = self.bot.get_updates(
  File "C:\Python39\lib\site-packages\telegram\bot.py", line 117, in decorator
    result = func(*args, **kwargs)
  File "C:\Python39\lib\site-packages\telegram\bot.py", line 2725, in get_updates
    result = self._post(
  File "C:\Python39\lib\site-packages\telegram\bot.py", line 235, in _post
    return self.request.post(f'{self.base_url}/{endpoint}', data=data, timeout=timeout)
  File "C:\Python39\lib\site-packages\telegram\utils\request.py", line 349, in post
    result = self._request_wrapper(
  File "C:\Python39\lib\site-packages\telegram\utils\request.py", line 276, in _request_wrapper
    raise Conflict(message)
telegram.error.Conflict: Conflict: terminated by other getUpdates request; make sure that only one bot instance is running
22-Feb-21 10:30:53 - Received signal 2 (SIGINT), stopping...
22-Feb-21 10:30:53 - Scheduler has been shut down
22-Feb-21 10:30:53 - Exiting immediately!
22-Feb-21 10:30:55 - Бот стартовал
22-Feb-21 10:30:55 - Scheduler started
22-Feb-21 10:31:00 - Error while getting Updates: Conflict: terminated by other getUpdates request; make sure that only one bot instance is running
22-Feb-21 10:31:00 - No error handlers are registered, logging exception.
Traceback (most recent call last):
  File "C:\Python39\lib\site-packages\telegram\ext\updater.py", line 465, in _network_loop_retry
    if not action_cb():
  File "C:\Python39\lib\site-packages\telegram\ext\updater.py", line 416, in polling_action_cb
    updates = self.bot.get_updates(
  File "C:\Python39\lib\site-packages\telegram\bot.py", line 117, in decorator
    result = func(*args, **kwargs)
  File "C:\Python39\lib\site-packages\telegram\bot.py", line 2725, in get_updates
    result = self._post(
  File "C:\Python39\lib\site-packages\telegram\bot.py", line 235, in _post
    return self.request.post(f'{self.base_url}/{endpoint}', data=data, timeout=timeout)
  File "C:\Python39\lib\site-packages\telegram\utils\request.py", line 349, in post
    result = self._request_wrapper(
  File "C:\Python39\lib\site-packages\telegram\utils\request.py", line 276, in _request_wrapper
    raise Conflict(message)
telegram.error.Conflict: Conflict: terminated by other getUpdates request; make sure that only one bot instance is running
22-Feb-21 10:31:34 - Error while getting Updates: Conflict: terminated by other getUpdates request; make sure that only one bot instance is running
22-Feb-21 10:31:34 - No error handlers are registered, logging exception.
Traceback (most recent call last):
  File "C:\Python39\lib\site-packages\telegram\ext\updater.py", line 465, in _network_loop_retry
    if not action_cb():
  File "C:\Python39\lib\site-packages\telegram\ext\updater.py", line 416, in polling_action_cb
    updates = self.bot.get_updates(
  File "C:\Python39\lib\site-packages\telegram\bot.py", line 117, in decorator
    result = func(*args, **kwargs)
  File "C:\Python39\lib\site-packages\telegram\bot.py", line 2725, in get_updates
    result = self._post(
  File "C:\Python39\lib\site-packages\telegram\bot.py", line 235, in _post
    return self.request.post(f'{self.base_url}/{endpoint}', data=data, timeout=timeout)
  File "C:\Python39\lib\site-packages\telegram\utils\request.py", line 349, in post
    result = self._request_wrapper(
  File "C:\Python39\lib\site-packages\telegram\utils\request.py", line 276, in _request_wrapper
    raise Conflict(message)
telegram.error.Conflict: Conflict: terminated by other getUpdates request; make sure that only one bot instance is running
22-Feb-21 10:31:40 - Received signal 2 (SIGINT), stopping...
22-Feb-21 10:31:40 - Scheduler has been shut down
22-Feb-21 10:31:40 - Exiting immediately!
22-Feb-21 10:31:45 - Бот стартовал
22-Feb-21 10:31:45 - Scheduler started
22-Feb-21 10:31:57 - No error handlers are registered, logging exception.
Traceback (most recent call last):
  File "C:\Python39\lib\site-packages\telegram\ext\dispatcher.py", line 442, in process_update
    handler.handle_update(update, self, check, context)
  File "C:\Python39\lib\site-packages\telegram\ext\handler.py", line 160, in handle_update
    return self.callback(update, context)
  File "C:\LearnPython\lesson1\bot\learn_python_alex_bot1.py", line 16, in planets_request
    user_planet = update.message.text.split([0])
TypeError: must be str or None, not list
22-Feb-21 10:32:08 - Error while getting Updates: Conflict: terminated by other getUpdates request; make sure that only one bot instance is running
22-Feb-21 10:32:08 - No error handlers are registered, logging exception.
Traceback (most recent call last):
  File "C:\Python39\lib\site-packages\telegram\ext\updater.py", line 465, in _network_loop_retry
    if not action_cb():
  File "C:\Python39\lib\site-packages\telegram\ext\updater.py", line 416, in polling_action_cb
    updates = self.bot.get_updates(
  File "C:\Python39\lib\site-packages\telegram\bot.py", line 117, in decorator
    result = func(*args, **kwargs)
  File "C:\Python39\lib\site-packages\telegram\bot.py", line 2725, in get_updates
    result = self._post(
  File "C:\Python39\lib\site-packages\telegram\bot.py", line 235, in _post
    return self.request.post(f'{self.base_url}/{endpoint}', data=data, timeout=timeout)
  File "C:\Python39\lib\site-packages\telegram\utils\request.py", line 349, in post
    result = self._request_wrapper(
  File "C:\Python39\lib\site-packages\telegram\utils\request.py", line 276, in _request_wrapper
    raise Conflict(message)
telegram.error.Conflict: Conflict: terminated by other getUpdates request; make sure that only one bot instance is running
22-Feb-21 10:32:27 - Received signal 2 (SIGINT), stopping...
22-Feb-21 10:32:27 - Scheduler has been shut down
22-Feb-21 10:32:28 - Exiting immediately!
22-Feb-21 10:32:29 - Бот стартовал
22-Feb-21 10:32:29 - Scheduler started
22-Feb-21 10:32:43 - Error while getting Updates: Conflict: terminated by other getUpdates request; make sure that only one bot instance is running
22-Feb-21 10:32:43 - No error handlers are registered, logging exception.
Traceback (most recent call last):
  File "C:\Python39\lib\site-packages\telegram\ext\updater.py", line 465, in _network_loop_retry
    if not action_cb():
  File "C:\Python39\lib\site-packages\telegram\ext\updater.py", line 416, in polling_action_cb
    updates = self.bot.get_updates(
  File "C:\Python39\lib\site-packages\telegram\bot.py", line 117, in decorator
    result = func(*args, **kwargs)
  File "C:\Python39\lib\site-packages\telegram\bot.py", line 2725, in get_updates
    result = self._post(
  File "C:\Python39\lib\site-packages\telegram\bot.py", line 235, in _post
    return self.request.post(f'{self.base_url}/{endpoint}', data=data, timeout=timeout)
  File "C:\Python39\lib\site-packages\telegram\utils\request.py", line 349, in post
    result = self._request_wrapper(
  File "C:\Python39\lib\site-packages\telegram\utils\request.py", line 276, in _request_wrapper
    raise Conflict(message)
telegram.error.Conflict: Conflict: terminated by other getUpdates request; make sure that only one bot instance is running
22-Feb-21 10:33:17 - Error while getting Updates: Conflict: terminated by other getUpdates request; make sure that only one bot instance is running
22-Feb-21 10:33:17 - No error handlers are registered, logging exception.
Traceback (most recent call last):
  File "C:\Python39\lib\site-packages\telegram\ext\updater.py", line 465, in _network_loop_retry
    if not action_cb():
  File "C:\Python39\lib\site-packages\telegram\ext\updater.py", line 416, in polling_action_cb
    updates = self.bot.get_updates(
  File "C:\Python39\lib\site-packages\telegram\bot.py", line 117, in decorator
    result = func(*args, **kwargs)
  File "C:\Python39\lib\site-packages\telegram\bot.py", line 2725, in get_updates
    result = self._post(
  File "C:\Python39\lib\site-packages\telegram\bot.py", line 235, in _post
    return self.request.post(f'{self.base_url}/{endpoint}', data=data, timeout=timeout)
  File "C:\Python39\lib\site-packages\telegram\utils\request.py", line 349, in post
    result = self._request_wrapper(
  File "C:\Python39\lib\site-packages\telegram\utils\request.py", line 276, in _request_wrapper
    raise Conflict(message)
telegram.error.Conflict: Conflict: terminated by other getUpdates request; make sure that only one bot instance is running
22-Feb-21 10:33:51 - Error while getting Updates: Conflict: terminated by other getUpdates request; make sure that only one bot instance is running
22-Feb-21 10:33:51 - No error handlers are registered, logging exception.
Traceback (most recent call last):
  File "C:\Python39\lib\site-packages\telegram\ext\updater.py", line 465, in _network_loop_retry
    if not action_cb():
  File "C:\Python39\lib\site-packages\telegram\ext\updater.py", line 416, in polling_action_cb
    updates = self.bot.get_updates(
  File "C:\Python39\lib\site-packages\telegram\bot.py", line 117, in decorator
    result = func(*args, **kwargs)
  File "C:\Python39\lib\site-packages\telegram\bot.py", line 2725, in get_updates
    result = self._post(
  File "C:\Python39\lib\site-packages\telegram\bot.py", line 235, in _post
    return self.request.post(f'{self.base_url}/{endpoint}', data=data, timeout=timeout)
  File "C:\Python39\lib\site-packages\telegram\utils\request.py", line 349, in post
    result = self._request_wrapper(
  File "C:\Python39\lib\site-packages\telegram\utils\request.py", line 276, in _request_wrapper
    raise Conflict(message)
telegram.error.Conflict: Conflict: terminated by other getUpdates request; make sure that only one bot instance is running
22-Feb-21 10:34:25 - Error while getting Updates: Conflict: terminated by other getUpdates request; make sure that only one bot instance is running
22-Feb-21 10:34:25 - No error handlers are registered, logging exception.
Traceback (most recent call last):
  File "C:\Python39\lib\site-packages\telegram\ext\updater.py", line 465, in _network_loop_retry
    if not action_cb():
  File "C:\Python39\lib\site-packages\telegram\ext\updater.py", line 416, in polling_action_cb
    updates = self.bot.get_updates(
  File "C:\Python39\lib\site-packages\telegram\bot.py", line 117, in decorator
    result = func(*args, **kwargs)
  File "C:\Python39\lib\site-packages\telegram\bot.py", line 2725, in get_updates
    result = self._post(
  File "C:\Python39\lib\site-packages\telegram\bot.py", line 235, in _post
    return self.request.post(f'{self.base_url}/{endpoint}', data=data, timeout=timeout)
  File "C:\Python39\lib\site-packages\telegram\utils\request.py", line 349, in post
    result = self._request_wrapper(
  File "C:\Python39\lib\site-packages\telegram\utils\request.py", line 276, in _request_wrapper
    raise Conflict(message)
telegram.error.Conflict: Conflict: terminated by other getUpdates request; make sure that only one bot instance is running
22-Feb-21 10:34:59 - Error while getting Updates: Conflict: terminated by other getUpdates request; make sure that only one bot instance is running
22-Feb-21 10:34:59 - No error handlers are registered, logging exception.
Traceback (most recent call last):
  File "C:\Python39\lib\site-packages\telegram\ext\updater.py", line 465, in _network_loop_retry
    if not action_cb():
  File "C:\Python39\lib\site-packages\telegram\ext\updater.py", line 416, in polling_action_cb
    updates = self.bot.get_updates(
  File "C:\Python39\lib\site-packages\telegram\bot.py", line 117, in decorator
    result = func(*args, **kwargs)
  File "C:\Python39\lib\site-packages\telegram\bot.py", line 2725, in get_updates
    result = self._post(
  File "C:\Python39\lib\site-packages\telegram\bot.py", line 235, in _post
    return self.request.post(f'{self.base_url}/{endpoint}', data=data, timeout=timeout)
  File "C:\Python39\lib\site-packages\telegram\utils\request.py", line 349, in post
    result = self._request_wrapper(
  File "C:\Python39\lib\site-packages\telegram\utils\request.py", line 276, in _request_wrapper
    raise Conflict(message)
telegram.error.Conflict: Conflict: terminated by other getUpdates request; make sure that only one bot instance is running
22-Feb-21 10:35:33 - Error while getting Updates: Conflict: terminated by other getUpdates request; make sure that only one bot instance is running
22-Feb-21 10:35:33 - No error handlers are registered, logging exception.
Traceback (most recent call last):
  File "C:\Python39\lib\site-packages\telegram\ext\updater.py", line 465, in _network_loop_retry
    if not action_cb():
  File "C:\Python39\lib\site-packages\telegram\ext\updater.py", line 416, in polling_action_cb
    updates = self.bot.get_updates(
  File "C:\Python39\lib\site-packages\telegram\bot.py", line 117, in decorator
    result = func(*args, **kwargs)
  File "C:\Python39\lib\site-packages\telegram\bot.py", line 2725, in get_updates
    result = self._post(
  File "C:\Python39\lib\site-packages\telegram\bot.py", line 235, in _post
    return self.request.post(f'{self.base_url}/{endpoint}', data=data, timeout=timeout)
  File "C:\Python39\lib\site-packages\telegram\utils\request.py", line 349, in post
    result = self._request_wrapper(
  File "C:\Python39\lib\site-packages\telegram\utils\request.py", line 276, in _request_wrapper
    raise Conflict(message)
telegram.error.Conflict: Conflict: terminated by other getUpdates request; make sure that only one bot instance is running
22-Feb-21 10:36:07 - Error while getting Updates: Conflict: terminated by other getUpdates request; make sure that only one bot instance is running
22-Feb-21 10:36:07 - No error handlers are registered, logging exception.
Traceback (most recent call last):
  File "C:\Python39\lib\site-packages\telegram\ext\updater.py", line 465, in _network_loop_retry
    if not action_cb():
  File "C:\Python39\lib\site-packages\telegram\ext\updater.py", line 416, in polling_action_cb
    updates = self.bot.get_updates(
  File "C:\Python39\lib\site-packages\telegram\bot.py", line 117, in decorator
    result = func(*args, **kwargs)
  File "C:\Python39\lib\site-packages\telegram\bot.py", line 2725, in get_updates
    result = self._post(
  File "C:\Python39\lib\site-packages\telegram\bot.py", line 235, in _post
    return self.request.post(f'{self.base_url}/{endpoint}', data=data, timeout=timeout)
  File "C:\Python39\lib\site-packages\telegram\utils\request.py", line 349, in post
    result = self._request_wrapper(
  File "C:\Python39\lib\site-packages\telegram\utils\request.py", line 276, in _request_wrapper
    raise Conflict(message)
telegram.error.Conflict: Conflict: terminated by other getUpdates request; make sure that only one bot instance is running
22-Feb-21 10:36:41 - Error while getting Updates: Conflict: terminated by other getUpdates request; make sure that only one bot instance is running
22-Feb-21 10:36:41 - No error handlers are registered, logging exception.
Traceback (most recent call last):
  File "C:\Python39\lib\site-packages\telegram\ext\updater.py", line 465, in _network_loop_retry
    if not action_cb():
  File "C:\Python39\lib\site-packages\telegram\ext\updater.py", line 416, in polling_action_cb
    updates = self.bot.get_updates(
  File "C:\Python39\lib\site-packages\telegram\bot.py", line 117, in decorator
    result = func(*args, **kwargs)
  File "C:\Python39\lib\site-packages\telegram\bot.py", line 2725, in get_updates
    result = self._post(
  File "C:\Python39\lib\site-packages\telegram\bot.py", line 235, in _post
    return self.request.post(f'{self.base_url}/{endpoint}', data=data, timeout=timeout)
  File "C:\Python39\lib\site-packages\telegram\utils\request.py", line 349, in post
    result = self._request_wrapper(
  File "C:\Python39\lib\site-packages\telegram\utils\request.py", line 276, in _request_wrapper
    raise Conflict(message)
telegram.error.Conflict: Conflict: terminated by other getUpdates request; make sure that only one bot instance is running
22-Feb-21 10:37:15 - Error while getting Updates: Conflict: terminated by other getUpdates request; make sure that only one bot instance is running
22-Feb-21 10:37:15 - No error handlers are registered, logging exception.
Traceback (most recent call last):
  File "C:\Python39\lib\site-packages\telegram\ext\updater.py", line 465, in _network_loop_retry
    if not action_cb():
  File "C:\Python39\lib\site-packages\telegram\ext\updater.py", line 416, in polling_action_cb
    updates = self.bot.get_updates(
  File "C:\Python39\lib\site-packages\telegram\bot.py", line 117, in decorator
    result = func(*args, **kwargs)
  File "C:\Python39\lib\site-packages\telegram\bot.py", line 2725, in get_updates
    result = self._post(
  File "C:\Python39\lib\site-packages\telegram\bot.py", line 235, in _post
    return self.request.post(f'{self.base_url}/{endpoint}', data=data, timeout=timeout)
  File "C:\Python39\lib\site-packages\telegram\utils\request.py", line 349, in post
    result = self._request_wrapper(
  File "C:\Python39\lib\site-packages\telegram\utils\request.py", line 276, in _request_wrapper
    raise Conflict(message)
telegram.error.Conflict: Conflict: terminated by other getUpdates request; make sure that only one bot instance is running
22-Feb-21 10:37:49 - Error while getting Updates: Conflict: terminated by other getUpdates request; make sure that only one bot instance is running
22-Feb-21 10:37:49 - No error handlers are registered, logging exception.
Traceback (most recent call last):
  File "C:\Python39\lib\site-packages\telegram\ext\updater.py", line 465, in _network_loop_retry
    if not action_cb():
  File "C:\Python39\lib\site-packages\telegram\ext\updater.py", line 416, in polling_action_cb
    updates = self.bot.get_updates(
  File "C:\Python39\lib\site-packages\telegram\bot.py", line 117, in decorator
    result = func(*args, **kwargs)
  File "C:\Python39\lib\site-packages\telegram\bot.py", line 2725, in get_updates
    result = self._post(
  File "C:\Python39\lib\site-packages\telegram\bot.py", line 235, in _post
    return self.request.post(f'{self.base_url}/{endpoint}', data=data, timeout=timeout)
  File "C:\Python39\lib\site-packages\telegram\utils\request.py", line 349, in post
    result = self._request_wrapper(
  File "C:\Python39\lib\site-packages\telegram\utils\request.py", line 276, in _request_wrapper
    raise Conflict(message)
telegram.error.Conflict: Conflict: terminated by other getUpdates request; make sure that only one bot instance is running
22-Feb-21 10:38:24 - Error while getting Updates: Conflict: terminated by other getUpdates request; make sure that only one bot instance is running
22-Feb-21 10:38:24 - No error handlers are registered, logging exception.
Traceback (most recent call last):
  File "C:\Python39\lib\site-packages\telegram\ext\updater.py", line 465, in _network_loop_retry
    if not action_cb():
  File "C:\Python39\lib\site-packages\telegram\ext\updater.py", line 416, in polling_action_cb
    updates = self.bot.get_updates(
  File "C:\Python39\lib\site-packages\telegram\bot.py", line 117, in decorator
    result = func(*args, **kwargs)
  File "C:\Python39\lib\site-packages\telegram\bot.py", line 2725, in get_updates
    result = self._post(
  File "C:\Python39\lib\site-packages\telegram\bot.py", line 235, in _post
    return self.request.post(f'{self.base_url}/{endpoint}', data=data, timeout=timeout)
  File "C:\Python39\lib\site-packages\telegram\utils\request.py", line 349, in post
    result = self._request_wrapper(
  File "C:\Python39\lib\site-packages\telegram\utils\request.py", line 276, in _request_wrapper
    raise Conflict(message)
telegram.error.Conflict: Conflict: terminated by other getUpdates request; make sure that only one bot instance is running
22-Feb-21 10:38:58 - Error while getting Updates: Conflict: terminated by other getUpdates request; make sure that only one bot instance is running
22-Feb-21 10:38:58 - No error handlers are registered, logging exception.
Traceback (most recent call last):
  File "C:\Python39\lib\site-packages\telegram\ext\updater.py", line 465, in _network_loop_retry
    if not action_cb():
  File "C:\Python39\lib\site-packages\telegram\ext\updater.py", line 416, in polling_action_cb
    updates = self.bot.get_updates(
  File "C:\Python39\lib\site-packages\telegram\bot.py", line 117, in decorator
    result = func(*args, **kwargs)
  File "C:\Python39\lib\site-packages\telegram\bot.py", line 2725, in get_updates
    result = self._post(
  File "C:\Python39\lib\site-packages\telegram\bot.py", line 235, in _post
    return self.request.post(f'{self.base_url}/{endpoint}', data=data, timeout=timeout)
  File "C:\Python39\lib\site-packages\telegram\utils\request.py", line 349, in post
    result = self._request_wrapper(
  File "C:\Python39\lib\site-packages\telegram\utils\request.py", line 276, in _request_wrapper
    raise Conflict(message)
telegram.error.Conflict: Conflict: terminated by other getUpdates request; make sure that only one bot instance is running
22-Feb-21 10:39:32 - Error while getting Updates: Conflict: terminated by other getUpdates request; make sure that only one bot instance is running
22-Feb-21 10:39:32 - No error handlers are registered, logging exception.
Traceback (most recent call last):
  File "C:\Python39\lib\site-packages\telegram\ext\updater.py", line 465, in _network_loop_retry
    if not action_cb():
  File "C:\Python39\lib\site-packages\telegram\ext\updater.py", line 416, in polling_action_cb
    updates = self.bot.get_updates(
  File "C:\Python39\lib\site-packages\telegram\bot.py", line 117, in decorator
    result = func(*args, **kwargs)
  File "C:\Python39\lib\site-packages\telegram\bot.py", line 2725, in get_updates
    result = self._post(
  File "C:\Python39\lib\site-packages\telegram\bot.py", line 235, in _post
    return self.request.post(f'{self.base_url}/{endpoint}', data=data, timeout=timeout)
  File "C:\Python39\lib\site-packages\telegram\utils\request.py", line 349, in post
    result = self._request_wrapper(
  File "C:\Python39\lib\site-packages\telegram\utils\request.py", line 276, in _request_wrapper
    raise Conflict(message)
telegram.error.Conflict: Conflict: terminated by other getUpdates request; make sure that only one bot instance is running
22-Feb-21 10:40:06 - Error while getting Updates: Conflict: terminated by other getUpdates request; make sure that only one bot instance is running
22-Feb-21 10:40:06 - No error handlers are registered, logging exception.
Traceback (most recent call last):
  File "C:\Python39\lib\site-packages\telegram\ext\updater.py", line 465, in _network_loop_retry
    if not action_cb():
  File "C:\Python39\lib\site-packages\telegram\ext\updater.py", line 416, in polling_action_cb
    updates = self.bot.get_updates(
  File "C:\Python39\lib\site-packages\telegram\bot.py", line 117, in decorator
    result = func(*args, **kwargs)
  File "C:\Python39\lib\site-packages\telegram\bot.py", line 2725, in get_updates
    result = self._post(
  File "C:\Python39\lib\site-packages\telegram\bot.py", line 235, in _post
    return self.request.post(f'{self.base_url}/{endpoint}', data=data, timeout=timeout)
  File "C:\Python39\lib\site-packages\telegram\utils\request.py", line 349, in post
    result = self._request_wrapper(
  File "C:\Python39\lib\site-packages\telegram\utils\request.py", line 276, in _request_wrapper
    raise Conflict(message)
telegram.error.Conflict: Conflict: terminated by other getUpdates request; make sure that only one bot instance is running
22-Feb-21 10:40:40 - Error while getting Updates: Conflict: terminated by other getUpdates request; make sure that only one bot instance is running
22-Feb-21 10:40:40 - No error handlers are registered, logging exception.
Traceback (most recent call last):
  File "C:\Python39\lib\site-packages\telegram\ext\updater.py", line 465, in _network_loop_retry
    if not action_cb():
  File "C:\Python39\lib\site-packages\telegram\ext\updater.py", line 416, in polling_action_cb
    updates = self.bot.get_updates(
  File "C:\Python39\lib\site-packages\telegram\bot.py", line 117, in decorator
    result = func(*args, **kwargs)
  File "C:\Python39\lib\site-packages\telegram\bot.py", line 2725, in get_updates
    result = self._post(
  File "C:\Python39\lib\site-packages\telegram\bot.py", line 235, in _post
    return self.request.post(f'{self.base_url}/{endpoint}', data=data, timeout=timeout)
  File "C:\Python39\lib\site-packages\telegram\utils\request.py", line 349, in post
    result = self._request_wrapper(
  File "C:\Python39\lib\site-packages\telegram\utils\request.py", line 276, in _request_wrapper
    raise Conflict(message)
telegram.error.Conflict: Conflict: terminated by other getUpdates request; make sure that only one bot instance is running
22-Feb-21 10:41:14 - Error while getting Updates: Conflict: terminated by other getUpdates request; make sure that only one bot instance is running
22-Feb-21 10:41:14 - No error handlers are registered, logging exception.
Traceback (most recent call last):
  File "C:\Python39\lib\site-packages\telegram\ext\updater.py", line 465, in _network_loop_retry
    if not action_cb():
  File "C:\Python39\lib\site-packages\telegram\ext\updater.py", line 416, in polling_action_cb
    updates = self.bot.get_updates(
  File "C:\Python39\lib\site-packages\telegram\bot.py", line 117, in decorator
    result = func(*args, **kwargs)
  File "C:\Python39\lib\site-packages\telegram\bot.py", line 2725, in get_updates
    result = self._post(
  File "C:\Python39\lib\site-packages\telegram\bot.py", line 235, in _post
    return self.request.post(f'{self.base_url}/{endpoint}', data=data, timeout=timeout)
  File "C:\Python39\lib\site-packages\telegram\utils\request.py", line 349, in post
    result = self._request_wrapper(
  File "C:\Python39\lib\site-packages\telegram\utils\request.py", line 276, in _request_wrapper
    raise Conflict(message)
telegram.error.Conflict: Conflict: terminated by other getUpdates request; make sure that only one bot instance is running
22-Feb-21 10:41:48 - Error while getting Updates: Conflict: terminated by other getUpdates request; make sure that only one bot instance is running
22-Feb-21 10:41:48 - No error handlers are registered, logging exception.
Traceback (most recent call last):
  File "C:\Python39\lib\site-packages\telegram\ext\updater.py", line 465, in _network_loop_retry
    if not action_cb():
  File "C:\Python39\lib\site-packages\telegram\ext\updater.py", line 416, in polling_action_cb
    updates = self.bot.get_updates(
  File "C:\Python39\lib\site-packages\telegram\bot.py", line 117, in decorator
    result = func(*args, **kwargs)
  File "C:\Python39\lib\site-packages\telegram\bot.py", line 2725, in get_updates
    result = self._post(
  File "C:\Python39\lib\site-packages\telegram\bot.py", line 235, in _post
    return self.request.post(f'{self.base_url}/{endpoint}', data=data, timeout=timeout)
  File "C:\Python39\lib\site-packages\telegram\utils\request.py", line 349, in post
    result = self._request_wrapper(
  File "C:\Python39\lib\site-packages\telegram\utils\request.py", line 276, in _request_wrapper
    raise Conflict(message)
telegram.error.Conflict: Conflict: terminated by other getUpdates request; make sure that only one bot instance is running
22-Feb-21 10:42:22 - Error while getting Updates: Conflict: terminated by other getUpdates request; make sure that only one bot instance is running
22-Feb-21 10:42:22 - No error handlers are registered, logging exception.
Traceback (most recent call last):
  File "C:\Python39\lib\site-packages\telegram\ext\updater.py", line 465, in _network_loop_retry
    if not action_cb():
  File "C:\Python39\lib\site-packages\telegram\ext\updater.py", line 416, in polling_action_cb
    updates = self.bot.get_updates(
  File "C:\Python39\lib\site-packages\telegram\bot.py", line 117, in decorator
    result = func(*args, **kwargs)
  File "C:\Python39\lib\site-packages\telegram\bot.py", line 2725, in get_updates
    result = self._post(
  File "C:\Python39\lib\site-packages\telegram\bot.py", line 235, in _post
    return self.request.post(f'{self.base_url}/{endpoint}', data=data, timeout=timeout)
  File "C:\Python39\lib\site-packages\telegram\utils\request.py", line 349, in post
    result = self._request_wrapper(
  File "C:\Python39\lib\site-packages\telegram\utils\request.py", line 276, in _request_wrapper
    raise Conflict(message)
telegram.error.Conflict: Conflict: terminated by other getUpdates request; make sure that only one bot instance is running
22-Feb-21 10:42:56 - Error while getting Updates: Conflict: terminated by other getUpdates request; make sure that only one bot instance is running
22-Feb-21 10:42:56 - No error handlers are registered, logging exception.
Traceback (most recent call last):
  File "C:\Python39\lib\site-packages\telegram\ext\updater.py", line 465, in _network_loop_retry
    if not action_cb():
  File "C:\Python39\lib\site-packages\telegram\ext\updater.py", line 416, in polling_action_cb
    updates = self.bot.get_updates(
  File "C:\Python39\lib\site-packages\telegram\bot.py", line 117, in decorator
    result = func(*args, **kwargs)
  File "C:\Python39\lib\site-packages\telegram\bot.py", line 2725, in get_updates
    result = self._post(
  File "C:\Python39\lib\site-packages\telegram\bot.py", line 235, in _post
    return self.request.post(f'{self.base_url}/{endpoint}', data=data, timeout=timeout)
  File "C:\Python39\lib\site-packages\telegram\utils\request.py", line 349, in post
    result = self._request_wrapper(
  File "C:\Python39\lib\site-packages\telegram\utils\request.py", line 276, in _request_wrapper
    raise Conflict(message)
telegram.error.Conflict: Conflict: terminated by other getUpdates request; make sure that only one bot instance is running
22-Feb-21 10:43:30 - Error while getting Updates: Conflict: terminated by other getUpdates request; make sure that only one bot instance is running
22-Feb-21 10:43:30 - No error handlers are registered, logging exception.
Traceback (most recent call last):
  File "C:\Python39\lib\site-packages\telegram\ext\updater.py", line 465, in _network_loop_retry
    if not action_cb():
  File "C:\Python39\lib\site-packages\telegram\ext\updater.py", line 416, in polling_action_cb
    updates = self.bot.get_updates(
  File "C:\Python39\lib\site-packages\telegram\bot.py", line 117, in decorator
    result = func(*args, **kwargs)
  File "C:\Python39\lib\site-packages\telegram\bot.py", line 2725, in get_updates
    result = self._post(
  File "C:\Python39\lib\site-packages\telegram\bot.py", line 235, in _post
    return self.request.post(f'{self.base_url}/{endpoint}', data=data, timeout=timeout)
  File "C:\Python39\lib\site-packages\telegram\utils\request.py", line 349, in post
    result = self._request_wrapper(
  File "C:\Python39\lib\site-packages\telegram\utils\request.py", line 276, in _request_wrapper
    raise Conflict(message)
telegram.error.Conflict: Conflict: terminated by other getUpdates request; make sure that only one bot instance is running
22-Feb-21 10:44:04 - Error while getting Updates: Conflict: terminated by other getUpdates request; make sure that only one bot instance is running
22-Feb-21 10:44:04 - No error handlers are registered, logging exception.
Traceback (most recent call last):
  File "C:\Python39\lib\site-packages\telegram\ext\updater.py", line 465, in _network_loop_retry
    if not action_cb():
  File "C:\Python39\lib\site-packages\telegram\ext\updater.py", line 416, in polling_action_cb
    updates = self.bot.get_updates(
  File "C:\Python39\lib\site-packages\telegram\bot.py", line 117, in decorator
    result = func(*args, **kwargs)
  File "C:\Python39\lib\site-packages\telegram\bot.py", line 2725, in get_updates
    result = self._post(
  File "C:\Python39\lib\site-packages\telegram\bot.py", line 235, in _post
    return self.request.post(f'{self.base_url}/{endpoint}', data=data, timeout=timeout)
  File "C:\Python39\lib\site-packages\telegram\utils\request.py", line 349, in post
    result = self._request_wrapper(
  File "C:\Python39\lib\site-packages\telegram\utils\request.py", line 276, in _request_wrapper
    raise Conflict(message)
telegram.error.Conflict: Conflict: terminated by other getUpdates request; make sure that only one bot instance is running
22-Feb-21 10:44:28 - Received signal 2 (SIGINT), stopping...
22-Feb-21 10:44:28 - Scheduler has been shut down
22-Feb-21 10:44:28 - Exiting immediately!
22-Feb-21 10:44:32 - Бот стартовал
22-Feb-21 10:44:32 - Scheduler started
22-Feb-21 10:44:39 - Error while getting Updates: Conflict: terminated by other getUpdates request; make sure that only one bot instance is running
22-Feb-21 10:44:39 - No error handlers are registered, logging exception.
Traceback (most recent call last):
  File "C:\Python39\lib\site-packages\telegram\ext\updater.py", line 465, in _network_loop_retry
    if not action_cb():
  File "C:\Python39\lib\site-packages\telegram\ext\updater.py", line 416, in polling_action_cb
    updates = self.bot.get_updates(
  File "C:\Python39\lib\site-packages\telegram\bot.py", line 117, in decorator
    result = func(*args, **kwargs)
  File "C:\Python39\lib\site-packages\telegram\bot.py", line 2725, in get_updates
    result = self._post(
  File "C:\Python39\lib\site-packages\telegram\bot.py", line 235, in _post
    return self.request.post(f'{self.base_url}/{endpoint}', data=data, timeout=timeout)
  File "C:\Python39\lib\site-packages\telegram\utils\request.py", line 349, in post
    result = self._request_wrapper(
  File "C:\Python39\lib\site-packages\telegram\utils\request.py", line 276, in _request_wrapper
    raise Conflict(message)
telegram.error.Conflict: Conflict: terminated by other getUpdates request; make sure that only one bot instance is running
22-Feb-21 10:45:13 - Error while getting Updates: Conflict: terminated by other getUpdates request; make sure that only one bot instance is running
22-Feb-21 10:45:13 - No error handlers are registered, logging exception.
Traceback (most recent call last):
  File "C:\Python39\lib\site-packages\telegram\ext\updater.py", line 465, in _network_loop_retry
    if not action_cb():
  File "C:\Python39\lib\site-packages\telegram\ext\updater.py", line 416, in polling_action_cb
    updates = self.bot.get_updates(
  File "C:\Python39\lib\site-packages\telegram\bot.py", line 117, in decorator
    result = func(*args, **kwargs)
  File "C:\Python39\lib\site-packages\telegram\bot.py", line 2725, in get_updates
    result = self._post(
  File "C:\Python39\lib\site-packages\telegram\bot.py", line 235, in _post
    return self.request.post(f'{self.base_url}/{endpoint}', data=data, timeout=timeout)
  File "C:\Python39\lib\site-packages\telegram\utils\request.py", line 349, in post
    result = self._request_wrapper(
  File "C:\Python39\lib\site-packages\telegram\utils\request.py", line 276, in _request_wrapper
    raise Conflict(message)
telegram.error.Conflict: Conflict: terminated by other getUpdates request; make sure that only one bot instance is running
22-Feb-21 10:45:47 - Error while getting Updates: Conflict: terminated by other getUpdates request; make sure that only one bot instance is running
22-Feb-21 10:45:47 - No error handlers are registered, logging exception.
Traceback (most recent call last):
  File "C:\Python39\lib\site-packages\telegram\ext\updater.py", line 465, in _network_loop_retry
    if not action_cb():
  File "C:\Python39\lib\site-packages\telegram\ext\updater.py", line 416, in polling_action_cb
    updates = self.bot.get_updates(
  File "C:\Python39\lib\site-packages\telegram\bot.py", line 117, in decorator
    result = func(*args, **kwargs)
  File "C:\Python39\lib\site-packages\telegram\bot.py", line 2725, in get_updates
    result = self._post(
  File "C:\Python39\lib\site-packages\telegram\bot.py", line 235, in _post
    return self.request.post(f'{self.base_url}/{endpoint}', data=data, timeout=timeout)
  File "C:\Python39\lib\site-packages\telegram\utils\request.py", line 349, in post
    result = self._request_wrapper(
  File "C:\Python39\lib\site-packages\telegram\utils\request.py", line 276, in _request_wrapper
    raise Conflict(message)
telegram.error.Conflict: Conflict: terminated by other getUpdates request; make sure that only one bot instance is running
22-Feb-21 10:46:21 - Error while getting Updates: Conflict: terminated by other getUpdates request; make sure that only one bot instance is running
22-Feb-21 10:46:21 - No error handlers are registered, logging exception.
Traceback (most recent call last):
  File "C:\Python39\lib\site-packages\telegram\ext\updater.py", line 465, in _network_loop_retry
    if not action_cb():
  File "C:\Python39\lib\site-packages\telegram\ext\updater.py", line 416, in polling_action_cb
    updates = self.bot.get_updates(
  File "C:\Python39\lib\site-packages\telegram\bot.py", line 117, in decorator
    result = func(*args, **kwargs)
  File "C:\Python39\lib\site-packages\telegram\bot.py", line 2725, in get_updates
    result = self._post(
  File "C:\Python39\lib\site-packages\telegram\bot.py", line 235, in _post
    return self.request.post(f'{self.base_url}/{endpoint}', data=data, timeout=timeout)
  File "C:\Python39\lib\site-packages\telegram\utils\request.py", line 349, in post
    result = self._request_wrapper(
  File "C:\Python39\lib\site-packages\telegram\utils\request.py", line 276, in _request_wrapper
    raise Conflict(message)
telegram.error.Conflict: Conflict: terminated by other getUpdates request; make sure that only one bot instance is running
22-Feb-21 10:46:55 - Error while getting Updates: Conflict: terminated by other getUpdates request; make sure that only one bot instance is running
22-Feb-21 10:46:55 - No error handlers are registered, logging exception.
Traceback (most recent call last):
  File "C:\Python39\lib\site-packages\telegram\ext\updater.py", line 465, in _network_loop_retry
    if not action_cb():
  File "C:\Python39\lib\site-packages\telegram\ext\updater.py", line 416, in polling_action_cb
    updates = self.bot.get_updates(
  File "C:\Python39\lib\site-packages\telegram\bot.py", line 117, in decorator
    result = func(*args, **kwargs)
  File "C:\Python39\lib\site-packages\telegram\bot.py", line 2725, in get_updates
    result = self._post(
  File "C:\Python39\lib\site-packages\telegram\bot.py", line 235, in _post
    return self.request.post(f'{self.base_url}/{endpoint}', data=data, timeout=timeout)
  File "C:\Python39\lib\site-packages\telegram\utils\request.py", line 349, in post
    result = self._request_wrapper(
  File "C:\Python39\lib\site-packages\telegram\utils\request.py", line 276, in _request_wrapper
    raise Conflict(message)
telegram.error.Conflict: Conflict: terminated by other getUpdates request; make sure that only one bot instance is running
22-Feb-21 10:47:29 - Error while getting Updates: Conflict: terminated by other getUpdates request; make sure that only one bot instance is running
22-Feb-21 10:47:29 - No error handlers are registered, logging exception.
Traceback (most recent call last):
  File "C:\Python39\lib\site-packages\telegram\ext\updater.py", line 465, in _network_loop_retry
    if not action_cb():
  File "C:\Python39\lib\site-packages\telegram\ext\updater.py", line 416, in polling_action_cb
    updates = self.bot.get_updates(
  File "C:\Python39\lib\site-packages\telegram\bot.py", line 117, in decorator
    result = func(*args, **kwargs)
  File "C:\Python39\lib\site-packages\telegram\bot.py", line 2725, in get_updates
    result = self._post(
  File "C:\Python39\lib\site-packages\telegram\bot.py", line 235, in _post
    return self.request.post(f'{self.base_url}/{endpoint}', data=data, timeout=timeout)
  File "C:\Python39\lib\site-packages\telegram\utils\request.py", line 349, in post
    result = self._request_wrapper(
  File "C:\Python39\lib\site-packages\telegram\utils\request.py", line 276, in _request_wrapper
    raise Conflict(message)
telegram.error.Conflict: Conflict: terminated by other getUpdates request; make sure that only one bot instance is running
22-Feb-21 10:48:03 - Error while getting Updates: Conflict: terminated by other getUpdates request; make sure that only one bot instance is running
22-Feb-21 10:48:03 - No error handlers are registered, logging exception.
Traceback (most recent call last):
  File "C:\Python39\lib\site-packages\telegram\ext\updater.py", line 465, in _network_loop_retry
    if not action_cb():
  File "C:\Python39\lib\site-packages\telegram\ext\updater.py", line 416, in polling_action_cb
    updates = self.bot.get_updates(
  File "C:\Python39\lib\site-packages\telegram\bot.py", line 117, in decorator
    result = func(*args, **kwargs)
  File "C:\Python39\lib\site-packages\telegram\bot.py", line 2725, in get_updates
    result = self._post(
  File "C:\Python39\lib\site-packages\telegram\bot.py", line 235, in _post
    return self.request.post(f'{self.base_url}/{endpoint}', data=data, timeout=timeout)
  File "C:\Python39\lib\site-packages\telegram\utils\request.py", line 349, in post
    result = self._request_wrapper(
  File "C:\Python39\lib\site-packages\telegram\utils\request.py", line 276, in _request_wrapper
    raise Conflict(message)
telegram.error.Conflict: Conflict: terminated by other getUpdates request; make sure that only one bot instance is running
22-Feb-21 10:48:33 - Received signal 2 (SIGINT), stopping...
22-Feb-21 10:48:33 - Scheduler has been shut down
22-Feb-21 10:48:34 - Exiting immediately!
22-Feb-21 16:09:38 - \u0411\u043e\u0442 \u0441\u0442\u0430\u0440\u0442\u043e\u0432\u0430\u043b
22-Feb-21 16:09:38 - Scheduler started
22-Feb-21 16:10:49 - Received signal 2 (SIGINT), stopping...
22-Feb-21 16:10:49 - Scheduler has been shut down
